{
  "comments": [
    {
      "unresolved": false,
      "key": {
        "uuid": "13ed067d_48d7fa36",
        "filename": "/PATCHSET_LEVEL",
        "patchSetId": 1
      },
      "lineNbr": 0,
      "author": {
        "id": 1326275
      },
      "writtenOn": "2020-12-16T00:56:01Z",
      "side": 1,
      "message": "Why did the first run fail but the 2nd one seems to have passed the analyze step?",
      "revId": "1c7a6939f470edd564e5e8e9c0767b839fd19e83",
      "serverId": "3ce6091f-6c88-37e8-8c75-72f92ae8dfba"
    }
  ]
}