{
  "comments": [
    {
      "unresolved": false,
      "key": {
        "uuid": "5c098ff0_35c5d6fd",
        "filename": "/PATCHSET_LEVEL",
        "patchSetId": 13
      },
      "lineNbr": 0,
      "author": {
        "id": 1329751
      },
      "writtenOn": "2022-05-12T16:00:41Z",
      "side": 1,
      "message": "Neat that you found a fix. I\u0027m wondering - what\u0027s causing the six error? Can we switch to Py3?",
      "revId": "aa5a3f9c66dbe02e1b4e9bcf8cd215b510f16ff6",
      "serverId": "3ce6091f-6c88-37e8-8c75-72f92ae8dfba"
    }
  ]
}